<?xml version="1.0" encoding="UTF-8"?>
<!-- Generated by org.testng.reporters.JUnitReportReporter -->
<testsuite skipped="0" hostname="Mai-Fathy" name="linkedinTestCases.ForgotPasswordTest" tests="5" failures="1" timestamp="01 Jul 2018 19:22:25 GMT" time="20.996" errors="0">
  <testcase name="Verfiy_the_system_keep_the_email" time="2.653" classname="linkedinTestCases.ForgotPasswordTest">
    <failure type="java.lang.AssertionError" message="expected [mf069886.test@gmail.com] but found []">
      <![CDATA[java.lang.AssertionError: expected [mf069886.test@gmail.com] but found []
at org.testng.Assert.fail(Assert.java:96)
at org.testng.Assert.failNotEquals(Assert.java:776)
at org.testng.Assert.assertEqualsImpl(Assert.java:137)
at org.testng.Assert.assertEquals(Assert.java:118)
at org.testng.Assert.assertEquals(Assert.java:453)
at org.testng.Assert.assertEquals(Assert.java:463)
at linkedinTestCases.ForgotPasswordTest.Verfiy_the_system_keep_the_email(ForgotPasswordTest.java:36)
at sun.reflect.NativeMethodAccessorImpl.invoke0(Native Method)
at sun.reflect.NativeMethodAccessorImpl.invoke(Unknown Source)
at sun.reflect.DelegatingMethodAccessorImpl.invoke(Unknown Source)
at java.lang.reflect.Method.invoke(Unknown Source)
at org.testng.internal.MethodInvocationHelper.invokeMethod(MethodInvocationHelper.java:124)
at org.testng.internal.Invoker.invokeMethod(Invoker.java:580)
at org.testng.internal.Invoker.invokeTestMethod(Invoker.java:716)
at org.testng.internal.Invoker.invokeTestMethods(Invoker.java:988)
at org.testng.internal.TestMethodWorker.invokeTestMethods(TestMethodWorker.java:125)
at org.testng.internal.TestMethodWorker.run(TestMethodWorker.java:109)
at org.testng.TestRunner.privateRun(TestRunner.java:648)
at org.testng.TestRunner.run(TestRunner.java:505)
at org.testng.SuiteRunner.runTest(SuiteRunner.java:455)
at org.testng.SuiteRunner.runSequentially(SuiteRunner.java:450)
at org.testng.SuiteRunner.privateRun(SuiteRunner.java:415)
at org.testng.SuiteRunner.run(SuiteRunner.java:364)
at org.testng.SuiteRunnerWorker.runSuite(SuiteRunnerWorker.java:52)
at org.testng.SuiteRunnerWorker.run(SuiteRunnerWorker.java:84)
at org.testng.TestNG.runSuitesSequentially(TestNG.java:1208)
at org.testng.TestNG.runSuitesLocally(TestNG.java:1137)
at org.testng.TestNG.runSuites(TestNG.java:1049)
at org.testng.TestNG.run(TestNG.java:1017)
at org.testng.remote.AbstractRemoteTestNG.run(AbstractRemoteTestNG.java:114)
at org.testng.remote.RemoteTestNG.initAndRun(RemoteTestNG.java:251)
at org.testng.remote.RemoteTestNG.main(RemoteTestNG.java:77)
]]>
    </failure>
  </testcase> <!-- Verfiy_the_system_keep_the_email -->
  <testcase name="Verfiy_the_system_display_MSG_For_invalid" time="5.199" classname="linkedinTestCases.ForgotPasswordTest"/>
  <testcase name="Verfiy_the_system_send_email_For_user" time="6.035" classname="linkedinTestCases.ForgotPasswordTest"/>
  <testcase name="Verfiy_the_user_can_open_forgetpassPage" time="1.888" classname="linkedinTestCases.ForgotPasswordTest"/>
  <testcase name="Verfiy_the_system_display_MSG_For_invalid" time="5.221" classname="linkedinTestCases.ForgotPasswordTest"/>
</testsuite> <!-- linkedinTestCases.ForgotPasswordTest -->
